Workbook

Sheet FLOTA
A1: CANNAVA | TABLA MAESTRA DE FLOTA
A2: PATENTE | B2: TIPO | C2: MARCA | D2: MODELO | E2: AÑO | F2: Nº CHASIS | G2: Nº MOTOR | H2: RESPONSABLE | I2: ESTADO % | J2: REQUIERE BATERÍA | K2: RODADO | L2: CUBIERTAS A CAMBIAR | M2: OBSERVACIONES
A3: NZU 308 | B3: CAMIONETA | C3: TOYOTA | D3: HILUX CD SRV 3.0 4X4 | E3: 2014 | F3: 8AJFZ29G5F6174551 | G3: 1KDA488133 | H3: SIN USO | I3: 0 | J3: SI | K3: 265-65-R17 | L3: 4 | M3: Inutilizable. Mantenimientos urgentes/pendientes.
A4: OFB 802 | B4: CAMIONETA | C4: FORD | D4: RANGER 2 CD 4X4 XLS 3.2L | E4: 2014 | F4: 8AFAR22JBFJ273114 | G4: QW2PFJ273114 | H4: FABIAN GONZALES | I4: 80 | J4: SI | K4: 255-70-R16 | L4: 2 | M4: Pedir garantía por reparaciones.
A5: GHQ 969 | B5: CAMIONETA | C5: TOYOTA | D5: PRADO LAND CRUISER | E5: 2007 | F5: JTEBY25J770054951 | G5: 1KZ1582466 | H5: SIN USO | I5: 30 | J5: SI | K5: 265-65-R17 | L5: 4 | M5: Inutilizable. Mantenimientos urgentes/pendientes.
A6: AA 757 OT | B6: CAMIONETA | C6: TOYOTA | D6: HILUX 4X2 CD SRV 3.0 | E6: 2016 | F6: 8AJEZ39G9C2537258 | G6: 1KD5810031 | H6: TOMAS VARGAS DURAN | I6: 50 | J6: NO | K6: 265-65-R17 | L6: 0 | M6: Negra.
A7: AC 442 VH | B7: CAMIONETA | C7: VOLKSWAGEN | D7: AMAROK CS 2.0 140CV | E7: 2018 | F7: 8AWSD42H2JA023873 | G7: CNF094651 | H7: SERENOS | I7: 85 | J7: NO | K7: 255-70-R16 | L7: 2
A8: MPR 852 | B8: CAMIONETA | C8: VOLKSWAGEN | D8: AMAROK CD 2.0 4X4 180CV | E8: 2013 | F8: 8AEDB22H7DA033757 | G8: CNE032930 | H8: SIN USO | I8: 30 | J8: SI | K8: 265-65-R17 | L8: 2 | M8: Inutilizable. Mantenimientos urgentes/pendientes.
A9: AA 932 XX | B9: CAMIONETA | C9: VOLKSWAGEN | D9: AMAROK DC 2.0L TDI 180CV 4X4 | E9: 2017 | F9: 8AWDB22H6HA004823 | G9: CNE094381 | H9: MARCELO GUASTELLA | I9: 80 | J9: NO | K9: 265-65-R17 | L9: 2
A10: PKF 116 | B10: MIDIBUS | C10: MERCEDES BENZ | D10: SPRINTER 515 CDIC | E10: 2016 | F10: 8AC906657GE117934 | G10: 651955W0055810 | H10: JOEL HUANUCO | I10: 80 | J10: SI | K10: 195-75-R16 | L10: 0
A11: AD 755 DX | B11: MIDIBUS | C11: MERCEDES BENZ | D11: SPRINTER 515 CDIC | E11: 2019 | F11: 8AC906657KE164683 | G11: 651955W0090281 | H11: FACUNDO RUIZ | I11: 75 | J11: NO | K11: 195-75-R16 | L11: 0
A12: AA 757 MH | B12: CAMIONETA | C12: FIAT | D12: TORO | E12: 2017 | H12: LUCAS CALVO | I12: 30 | J12: SI | K12: 225-65-R17 | L12: 2 | M12: Inutilizable. Mantenimientos urgentes/pendientes.

Sheet FLOTA TERCEROS
A1: CANNAVA | FLOTA TERCEROS (VEHÍCULOS ALQUILADOS)
A2: ⚠ Las celdas en amarillo están pendientes de completar — ESTADO ALQUILER: ACTIVO / FINALIZADO
A3: PATENTE | B3: TIPO | C3: MARCA | D3: MODELO | E3: AÑO | F3: PROVEEDOR / EMPRESA | G3: RESPONSABLE CANNAVA | H3: ESTADO ALQUILER | I3: ESTADO VEHÍCULO % | J3: OBSERVACIONES
A4: AG 164 FA | B4: CAMIONETA | C4: FORD | D4: RANGER | E4: → completar | F4: → completar | G4: → completar | H4: ACTIVO | I4: → completar | J4: Ranger alquilada — activa
A5: AG 164 FB | B5: CAMIONETA | C5: FORD | D5: RANGER | E5: → completar | F5: → completar | G5: JORGE ORLANDI | H5: FINALIZADO | I5: → completar | J5: contrato finalizado
A6: AG 164 EZ | B6: CAMIONETA | C6: FORD | D6: RANGER | E6: → completar | F6: → completar | G6: GASTON CURZI | H6: ACTIVO | I6: → completar | J6: Ranger alquilada — activa
A7: AD 209 YG | B7: COMBI | C7: MERCEDES BENZ | D7: → completar | E7: → completar | F7: → completar | G7: → completar | H7: FINALIZADO | I7: → completar | J7: Combi alquilada — contrato finalizado
A8: NAS 148 | B8: COMBI | C8: MERCEDES BENZ | D8: → completar | E8: → completar | F8: → completar | G8: → completar | H8: FINALIZADO | I8: → completar | J8: Combi alquilada — contrato finalizado
A9: AC 777 AA | B9: CAMIONETA | C9: CHEVROLET | D9: S10 | E9: → completar | F9: → completar | G9: → completar | H9: FINALIZADO | I9: → completar | J9: S10 alquilada — contrato finalizado

Sheet COMBUSTIBLE
A1: CANNAVA | REGISTRO DE CARGA DE COMBUSTIBLE | I1: TOTAL COMBUSTIBLE CARGADO | L1: =SUM(D3:D1018) -> 44505
A2: FECHA | B2: DOMINIO (PATENTE) | C2: VEHÍCULO ✦ | D2: LITROS | E2: KILOMETRAJE | F2: RESPONSABLE | G2: OBSERVACIONES
A3: 45591 | B3: MPR 852 | C3: =IF(B3="","",IFERROR(VLOOKUP(B3,FLOTA!$A:$D,4,0)&" — "&VLOOKUP(B3,FLOTA!$A:$D,3,0),IFERROR(VLOOKUP(B3,'FLOTA TERCEROS'!$A:$D,4,0)&" — "&VLOOKUP(B3,'FLOTA TERCEROS'!$A:$D,3,0),"⚠ No encontrado"))) -> AMAROK CD 2.0 4X4 180CV — VOLKSWAGEN | D3: 55 | E3: N/A | F3: Fabián Gonzales | Q3: NOMBRE DE RESPONSABLES
A4: 45591 | B4: AA 757 OT | C4: =IF(B4="","",IFERROR(VLOOKUP(B4,FLOTA!$A:$D,4,0)&" — "&VLOOKUP(B4,FLOTA!$A:$D,3,0),IFERROR(VLOOKUP(B4,'FLOTA TERCEROS'!$A:$D,4,0)&" — "&VLOOKUP(B4,'FLOTA TERCEROS'!$A:$D,3,0),"⚠ No encontrado"))) -> HILUX 4X2 CD SRV 3.0 — TOYOTA | D4: 30 | E4: N/A | F4: Nicolás Flores | Q4: Fabián Gonzales
A5: 45591 | B5: AD 209 YG | C5: =IF(B5="","",IFERROR(VLOOKUP(B5,FLOTA!$A:$D,4,0)&" — "&VLOOKUP(B5,FLOTA!$A:$D,3,0),IFERROR(VLOOKUP(B5,'FLOTA TERCEROS'!$A:$D,4,0)&" — "&VLOOKUP(B5,'FLOTA TERCEROS'!$A:$D,3,0),"⚠ No encontrado"))) -> → completar — MERCEDES BENZ | D5: 70 | E5: N/A | F5: Facundo Vilte | Q5: Nicolás Flores
A6: 45593 | B6: AD 755 DX | C6: =IF(B6="","",IFERROR(VLOOKUP(B6,FLOTA!$A:$D,4,0)&" — "&VLOOKUP(B6,FLOTA!$A:$D,3,0),IFERROR(VLOOKUP(B6,'FLOTA TERCEROS'!$A:$D,4,0)&" — "&VLOOKUP(B6,'FLOTA TERCEROS'!$A:$D,3,0),"⚠ No encontrado"))) -> SPRINTER 515 CDIC — MERCEDES BENZ | D6: 70 | E6: N/A | F6: Joel Huanuco | Q6: Facundo Vilte
A7: 45593 | B7: PKF 116 | C7: =IF(B7="","",IFERROR(VLOOKUP(B7,FLOTA!$A:$D,4,0)&" — "&VLOOKUP(B7,FLOTA!$A:$D,3,0),IFERROR(VLOOKUP(B7,'FLOTA TERCEROS'!$A:$D,4,0)&" — "&VLOOKUP(B7,'FLOTA TERCEROS'!$A:$D,3,0),"⚠ No encontrado"))) -> SPRINTER 515 CDIC — MERCEDES BENZ | D7: 75 | E7: N/A | F7: Facundo Ruiz | Q7: Joel Huanuco
A8: 45594 | B8: AG 164 FA | C8: =IF(B8="","",IFERROR(VLOOKUP(B8,FLOTA!$A:$D,4,0)&" — "&VLOOKUP(B8,FLOTA!$A:$D,3,0),IFERROR(VLOOKUP(B8,'FLOTA TERCEROS'!$A:$D,4,0)&" — "&VLOOKUP(B8,'FLOTA TERCEROS'!$A:$D,3,0),"⚠ No encontrado"))) -> RANGER — FORD | D8: 75 | E8: N/A | F8: Gastón Curzi | Q8: Facundo Ruiz
A9: 45595 | B9: AC 442 VH | C9: =IF(B9="","",IFERROR(VLOOKUP(B9,FLOTA!$A:$D,4,0)&" — "&VLOOKUP(B9,FLOTA!$A:$D,3,0),IFERROR(VLOOKUP(B9,'FLOTA TERCEROS'!$A:$D,4,0)&" — "&VLOOKUP(B9,'FLOTA TERCEROS'!$A:$D,3,0),"⚠ No encontrado"))) -> AMAROK CS 2.0 140CV — VOLKSWAGEN | D9: 60 | E9: N/A | F9: Aldo Rivera | Q9: Gastón Curzi
A10: 45595 | B10: AG 164 FB | C10: =IF(B10="","",IFERROR(VLOOKUP(B10,FLOTA!$A:$D,4,0)&" — "&VLOOKUP(B10,FLOTA!$A:$D,3,0),IFERROR(VLOOKUP(B10,'FLOTA TERCEROS'!$A:$D,4,0)&" — "&VLOOKUP(B10,'FLOTA TERCEROS'!$A:$D,3,0),"⚠ No encontrado"))) -> RANGER — FORD | D10: 60 | E10: N/A | F10: Jorge Orlandi | Q10: Aldo Rivera
A11: 45596 | B11: AA 757 OT | C11: =IF(B11="","",IFERROR(VLOOKUP(B11,FLOTA!$A:$D,4,0)&" — "&VLOOKUP(B11,FLOTA!$A:$D,3,0),IFERROR(VLOOKUP(B11,'FLOTA TERCEROS'!$A:$D,4,0)&" — "&VLOOKUP(B11,'FLOTA TERCEROS'!$A:$D,3,0),"⚠ No encontrado"))) -> HILUX 4X2 CD SRV 3.0 — TOYOTA | D11: 50 | E11: N/A | F11: Nicolás Flores | Q11: Jorge Orlandi
A12: 45596 | B12: AD 755 DX | C12: =IF(B12="","",IFERROR(VLOOKUP(B12,FLOTA!$A:$D,4,0)&" — "&VLOOKUP(B12,FLOTA!$A:$D,3,0),IFERROR(VLOOKUP(B12,'FLOTA TERCEROS'!$A:$D,4,0)&" — "&VLOOKUP(B12,'FLOTA TERCEROS'!$A:$D,3,0),"⚠ No encontrado"))) -> SPRINTER 515 CDIC — MERCEDES BENZ | D12: 55 | E12: N/A | F12: Joel Huanuco | Q12: Silvia Suarez
A13: 45596 | B13: AC 777 AA | C13: =IF(B13="","",IFERROR(VLOOKUP(B13,FLOTA!$A:$D,4,0)&" — "&VLOOKUP(B13,FLOTA!$A:$D,3,0),IFERROR(VLOOKUP(B13,'FLOTA TERCEROS'!$A:$D,4,0)&" — "&VLOOKUP(B13,'FLOTA TERCEROS'!$A:$D,3,0),"⚠ No encontrado"))) -> S10 — CHEVROLET | D13: 50 | E13: N/A | F13: Silvia Suarez | Q13: José Diaz
A14: 45597 | B14: PKF 116 | C14: =IF(B14="","",IFERROR(VLOOKUP(B14,FLOTA!$A:$D,4,0)&" — "&VLOOKUP(B14,FLOTA!$A:$D,3,0),IFERROR(VLOOKUP(B14,'FLOTA TERCEROS'!$A:$D,4,0)&" — "&VLOOKUP(B14,'FLOTA TERCEROS'!$A:$D,3,0),"⚠ No encontrado"))) -> SPRINTER 515 CDIC — MERCEDES BENZ | D14: 60 | E14: N/A | F14: Facundo Ruiz | Q14: René Reyes
... A22: 45601 | B22: AG 164 FA | C22: =IF(B22="","",IFERROR(VLOOKUP(B22,FLOTA!$A:$D,4,0)&" — "&VLOOKUP(B22,FLOTA!$A:$D,3,0),IFERROR(VLOOKUP(B22,'FLOTA TERCEROS'!$A:$D,4,0)&" — "&VLOOKUP(B22,'FLOTA TERCEROS'!$A:$D,3,0),"⚠ No encontrado"))) -> RANGER — FORD | D22: 80 | E22: N/A | F22: Gastón Curzi | Q22: Jose Diaz
A23: 45601 | B23: AC 442 VH | C23: =IF(B23="","",IFERROR(VLOOKUP(B23,FLOTA!$A:$D,4,0)&" — "&VLOOKUP(B23,FLOTA!$A:$D,3,0),IFERROR(VLOOKUP(B23,'FLOTA TERCEROS'!$A:$D,4,0)&" — "&VLOOKUP(B23,'FLOTA TERCEROS'!$A:$D,3,0),"⚠ No encontrado"))) -> AMAROK CS 2.0 140CV — VOLKSWAGEN | D23: 80 | E23: N/A | F23: Aldo Rivera
A24: 45605 | B24: AD 755 DX | C24: =IF(B24="","",IFERROR(VLOOKUP(B24,FLOTA!$A:$D,4,0)&" — "&VLOOKUP(B24,FLOTA!$A:$D,3,0),IFERROR(VLOOKUP(B24,'FLOTA TERCEROS'!$A:$D,4,0)&" — "&VLOOKUP(B24,'FLOTA TERCEROS'!$A:$D,3,0),"⚠ No encontrado"))) -> SPRINTER 515 CDIC — MERCEDES BENZ | D24: 65 | E24: N/A | F24: Joel Huanuco
A25: 45605 | B25: AG 164 FA | C25: =IF(B25="","",IFERROR(VLOOKUP(B25,FLOTA!$A:$D,4,0)&" — "&VLOOKUP(B25,FLOTA!$A:$D,3,0),IFERROR(VLOOKUP(B25,'FLOTA TERCEROS'!$A:$D,4,0)&" — "&VLOOKUP(B25,'FLOTA TERCEROS'!$A:$D,3,0),"⚠ No encontrado"))) -> RANGER — FORD | D25: 40 | E25: N/A | F25: José Diaz
A26: 45608 | B26: AD 209 YG | C26: =IF(B26="","",IFERROR(VLOOKUP(B26,FLOTA!$A:$D,4,0)&" — "&VLOOKUP(B26,FLOTA!$A:$D,3,0),IFERROR(VLOOKUP(B26,'FLOTA TERCEROS'!$A:$D,4,0)&" — "&VLOOKUP(B26,'FLOTA TERCEROS'!$A:$D,3,0),"⚠ No encontrado"))) -> → completar — MERCEDES BENZ | D26: 50 | E26: N/A | F26: Facundo Vilte
A27: 45608 | B27: PKF 116 | C27: =IF(B27="","",IFERROR(VLOOKUP(B27,FLOTA!$A:$D,4,0)&" — "&VLOOKUP(B27,FLOTA!$A:$D,3,0),IFERROR(VLOOKUP(B27,'FLOTA TERCEROS'!$A:$D,4,0)&" — "&VLOOKUP(B27,'FLOTA TERCEROS'!$A:$D,3,0),"⚠ No encontrado"))) -> SPRINTER 515 CDIC — MERCEDES BENZ | D27: 60 | E27: N/A | F27: Facundo Ruiz
A28: 45608 | B28: AG 164 FB | C28: =IF(B28="","",IFERROR(VLOOKUP(B28,FLOTA!$A:$D,4,0)&" — "&VLOOKUP(B28,FLOTA!$A:$D,3,0),IFERROR(VLOOKUP(B28,'FLOTA TERCEROS'!$A:$D,4,0)&" — "&VLOOKUP(B28,'FLOTA TERCEROS'!$A:$D,3,0),"⚠ No encontrado"))) -> RANGER — FORD | D28: 55 | E28: N/A | F28: Jorge Orlandi
A29: 45608 | B29: AG 164 FA | C29: =IF(B29="","",IFERROR(VLOOKUP(B29,FLOTA!$A:$D,4,0)&" — "&VLOOKUP(B29,FLOTA!$A:$D,3,0),IFERROR(VLOOKUP(B29,'FLOTA TERCEROS'!$A:$D,4,0)&" — "&VLOOKUP(B29,'FLOTA TERCEROS'!$A:$D,3,0),"⚠ No encontrado"))) -> RANGER — FORD | D29: 50 | E29: N/A | F29: Gastón Curzi
A30: 45608 | B30: AC 442 VH | C30: =IF(B30="","",IFERROR(VLOOKUP(B30,FLOTA!$A:$D,4,0)&" — "&VLOOKUP(B30,FLOTA!$A:$D,3,0),IFERROR(VLOOKUP(B30,'FLOTA TERCEROS'!$A:$D,4,0)&" — "&VLOOKUP(B30,'FLOTA TERCEROS'!$A:$D,3,0),"⚠ No encontrado"))) -> AMAROK CS 2.0 140CV — VOLKSWAGEN | D30: 60 | E30: N/A | F30: Aldo Rivera
A31: 45608 | B31: AA 757 OT | C31: =IF(B31="","",IFERROR(VLOOKUP(B31,FLOTA!$A:$D,4,0)&" — "&VLOOKUP(B31,FLOTA!$A:$D,3,0),IFERROR(VLOOKUP(B31,'FLOTA TERCEROS'!$A:$D,4,0)&" — "&VLOOKUP(B31,'FLOTA TERCEROS'!$A:$D,3,0),"⚠ No encontrado"))) -> HILUX 4X2 CD SRV 3.0 — TOYOTA | D31: 55 | E31: N/A | F31: Nicolás Flores
A32: 45609 | B32: AC 777 AA | C32: =IF(B32="","",IFERROR(VLOOKUP(B32,FLOTA!$A:$D,4,0)&" — "&VLOOKUP(B32,FLOTA!$A:$D,3,0),IFERROR(VLOOKUP(B32,'FLOTA TERCEROS'!$A:$D,4,0)&" — "&VLOOKUP(B32,'FLOTA TERCEROS'!$A:$D,3,0),"⚠ No encontrado"))) -> S10 — CHEVROLET | D32: 60 | E32: N/A | F32: Silvia Suarez
A33: 45610 | B33: AD 755 DX | C33: =IF(B33="","",IFERROR(VLOOKUP(B33,FLOTA!$A:$D,4,0)&" — "&VLOOKUP(B33,FLOTA!$A:$D,3,0),IFERROR(VLOOKUP(B33,'FLOTA TERCEROS'!$A:$D,4,0)&" — "&VLOOKUP(B33,'FLOTA TERCEROS'!$A:$D,3,0),"⚠ No encontrado"))) -> SPRINTER 515 CDIC — MERCEDES BENZ | D33: 70 | E33: N/A | F33: Joel Huanuco
A34: 45611 | B34: MPR 852 | C34: =IF(B34="","",IFERROR(VLOOKUP(B34,FLOTA!$A:$D,4,0)&" — "&VLOOKUP(B34,FLOTA!$A:$D,3,0),IFERROR(VLOOKUP(B34,'FLOTA TERCEROS'!$A:$D,4,0)&" — "&VLOOKUP(B34,'FLOTA TERCEROS'!$A:$D,3,0),"⚠ No encontrado"))) -> AMAROK CD 2.0 4X4 180CV — VOLKSWAGEN | D34: 75 | E34: N/A | F34: Fabián Gonzales
... A144: 45700 | B144: PKF 116 | C144: =IF(B144="","",IFERROR(VLOOKUP(B144,FLOTA!$A:$D,4,0)&" — "&VLOOKUP(B144,FLOTA!$A:$D,3,0),IFERROR(VLOOKUP(B144,'FLOTA TERCEROS'!$A:$D,4,0)&" — "&VLOOKUP(B144,'FLOTA TERCEROS'!$A:$D,3,0),"⚠ No encontrado"))) -> SPRINTER 515 CDIC — MERCEDES BENZ | D144: 67 | E144: N/A | F144: René Reyes
A145: 45700 | B145: MPR 852 | C145: =IF(B145="","",IFERROR(VLOOKUP(B145,FLOTA!$A:$D,4,0)&" — "&VLOOKUP(B145,FLOTA!$A:$D,3,0),IFERROR(VLOOKUP(B145,'FLOTA TERCEROS'!$A:$D,4,0)&" — "&VLOOKUP(B145,'FLOTA TERCEROS'!$A:$D,3,0),"⚠ No encontrado"))) -> AMAROK CD 2.0 4X4 180CV — VOLKSWAGEN | D145: 60 | E145: N/A | F145: Joel Huanuco | G145: Personal Seguridad y P.
A146: 45700 | B146: AA 757 OT | C146: =IF(B146="","",IFERROR(VLOOKUP(B146,FLOTA!$A:$D,4,0)&" — "&VLOOKUP(B146,FLOTA!$A:$D,3,0),IFERROR(VLOOKUP(B146,'FLOTA TERCEROS'!$A:$D,4,0)&" — "&VLOOKUP(B146,'FLOTA TERCEROS'!$A:$D,3,0),"⚠ No encontrado"))) -> HILUX 4X2 CD SRV 3.0 — TOYOTA | D146: 60 | E146: N/A | F146: Nicolás Flores
A147: 45700 | B147: AA 932 XX | C147: =IF(B147="","",IFERROR(VLOOKUP(B147,FLOTA!$A:$D,4,0)&" — "&VLOOKUP(B147,FLOTA!$A:$D,3,0),IFERROR(VLOOKUP(B147,'FLOTA TERCEROS'!$A:$D,4,0)&" — "&VLOOKUP(B147,'FLOTA TERCEROS'!$A:$D,3,0),"⚠ No encontrado"))) -> AMAROK DC 2.0L TDI 180CV 4X4 — VOLKSWAGEN | D147: 70 | E147: N/A | F147: Lucas Calvó | G147: Personal Seguridad y P.
A148: 45700 | B148: PKF 116 | C148: =IF(B148="","",IFERROR(VLOOKUP(B148,FLOTA!$A:$D,4,0)&" — "&VLOOKUP(B148,FLOTA!$A:$D,3,0),IFERROR(VLOOKUP(B148,'FLOTA TERCEROS'!$A:$D,4,0)&" — "&VLOOKUP(B148,'FLOTA TERCEROS'!$A:$D,3,0),"⚠ No encontrado"))) -> SPRINTER 515 CDIC — MERCEDES BENZ | D148: 60 | E148: N/A | F148: René Reyes
A149: 45703 | B149: AD 209 YG | C149: =IF(B149="","",IFERROR(VLOOKUP(B149,FLOTA!$A:$D,4,0)&" — "&VLOOKUP(B149,FLOTA!$A:$D,3,0),IFERROR(VLOOKUP(B149,'FLOTA TERCEROS'!$A:$D,4,0)&" — "&VLOOKUP(B149,'FLOTA TERCEROS'!$A:$D,3,0),"⚠ No encontrado"))) -> → completar — MERCEDES BENZ | D149: 30 | E149: N/A | F149: Facundo Vilte
A150: 45703 | B150: MPR 852 | C150: =IF(B150="","",IFERROR(VLOOKUP(B150,FLOTA!$A:$D,4,0)&" — "&VLOOKUP(B150,FLOTA!$A:$D,3,0),IFERROR(VLOOKUP(B150,'FLOTA TERCEROS'!$A:$D,4,0)&" — "&VLOOKUP(B150,'FLOTA TERCEROS'!$A:$D,3,0),"⚠ No encontrado"))) -> AMAROK CD 2.0 4X4 180CV — VOLKSWAGEN | D150: 50 | E150: N/A | F150: José Diaz | G150: Personal Seguridad y P.
A151: 45705 | B151: AA 932 XX | C151: =IF(B151="","",IFERROR(VLOOKUP(B151,FLOTA!$A:$D,4,0)&" — "&VLOOKUP(B151,FLOTA!$A:$D,3,0),IFERROR(VLOOKUP(B151,'FLOTA TERCEROS'!$A:$D,4,0)&" — "&VLOOKUP(B151,'FLOTA TERCEROS'!$A:$D,3,0),"⚠ No encontrado"))) -> AMAROK DC 2.0L TDI 180CV 4X4 — VOLKSWAGEN | D151: 60 | E151: N/A | F151: Lucas Calvó
A152: 45705 | B152: AD 209 YG | C152: =IF(B152="","",IFERROR(VLOOKUP(B152,FLOTA!$A:$D,4,0)&" — "&VLOOKUP(B152,FLOTA!$A:$D,3,0),IFERROR(VLOOKUP(B152,'FLOTA TERCEROS'!$A:$D,4,0)&" — "&VLOOKUP(B152,'FLOTA TERCEROS'!$A:$D,3,0),"⚠ No encontrado"))) -> → completar — MERCEDES BENZ | D152: 60 | E152: N/A | F152: Facundo Vilte
A153: 45705 | B153: MPR 852 | C153: =IF(B153="","",IFERROR(VLOOKUP(B153,FLOTA!$A:$D,4,0)&" — "&VLOOKUP(B153,FLOTA!$A:$D,3,0),IFERROR(VLOOKUP(B153,'FLOTA TERCEROS'!$A:$D,4,0)&" — "&VLOOKUP(B153,'FLOTA TERCEROS'!$A:$D,3,0),"⚠ No encontrado"))) -> AMAROK CD 2.0 4X4 180CV — VOLKSWAGEN | D153: 70 | E153: N/A | F153: Joel Huanuco
A154: 45706 | B154: PKF 116 | C154: =IF(B154="","",IFERROR(VLOOKUP(B154,FLOTA!$A:$D,4,0)&" — "&VLOOKUP(B154,FLOTA!$A:$D,3,0),IFERROR(VLOOKUP(B154,'FLOTA TERCEROS'!$A:$D,4,0)&" — "&VLOOKUP(B154,'FLOTA TERCEROS'!$A:$D,3,0),"⚠ No encontrado"))) -> SPRINTER 515 CDIC — MERCEDES BENZ | D154: 50 | E154: N/A | F154: René Reyes
A155: 45706 | B155: AA 932 XX | C155: =IF(B155="","",IFERROR(VLOOKUP(B155,FLOTA!$A:$D,4,0)&" — "&VLOOKUP(B155,FLOTA!$A:$D,3,0),IFERROR(VLOOKUP(B155,'FLOTA TERCEROS'!$A:$D,4,0)&" — "&VLOOKUP(B155,'FLOTA TERCEROS'!$A:$D,3,0),"⚠ No encontrado"))) -> AMAROK DC 2.0L TDI 180CV 4X4 — VOLKSWAGEN | D155: 55 | E155: N/A | F155: Lucas Calvó
A156: 45707 | B156: AG 164 FA | C156: =IF(B156="","",IFERROR(VLOOKUP(B156,FLOTA!$A:$D,4,0)&" — "&VLOOKUP(B156,FLOTA!$A:$D,3,0),IFERROR(VLOOKUP(B156,'FLOTA TERCEROS'!$A:$D,4,0)&" — "&VLOOKUP(B156,'FLOTA TERCEROS'!$A:$D,3,0),"⚠ No encontrado"))) -> RANGER — FORD | D156: 50 | E156: N/A | F156: Jorge Orlandi
...

Sheet ESTADO DE FLOTA
A1: CANNAVA | ESTADO DE FLOTA Y REPARACIONES
A2: PATENTE | B2: VEHÍCULO ✦ | C2: FECHA | D2: ESTADO | E2: TIPO DE REPARACIÓN | F2: PROVEEDOR 1 | G2: PRESUPUESTO 1 ($) | H2: M.O. 1 ($) | I2: TOTAL 1 ($) ✦ | J2: PROVEEDOR 2 | K2: PRESUPUESTO 2 ($) | L2: M.O. 2 ($) | M2: TOTAL 2 ($) ✦ | N2: OBSERVACIONES GENERALES | P2: ✦ = Auto-completado, no editar
A3: GHQ 969 | B3: =IF(A3="","",IFERROR(VLOOKUP(A3,FLOTA!$A:$M,4,0)&" "&VLOOKUP(A3,FLOTA!$A:$M,3,0),"⚠ Patente no encontrada")) -> PRADO LAND CRUISER TOYOTA | C3: 46078 | D3: PENDIENTE | E3: SERVICE DE MOTOR | I3: =IF(AND(G3="",H3=""),"",IF(G3="",H3,IF(H3="",G3,H3+G3))) | M3: =IF(AND(K3="",L3=""),"",IF(L3="",K3,IF(K3="",L3,K3+L3)))
A4: GHQ 969 | B4: =IF(A4="","",IFERROR(VLOOKUP(A4,FLOTA!$A:$M,4,0)&" "&VLOOKUP(A4,FLOTA!$A:$M,3,0),"⚠ Patente no encontrada")) -> PRADO LAND CRUISER TOYOTA | C4: 46078 | D4: PENDIENTE | E4: TREN DELANTERO COMPLETO | I4: =IF(AND(G4="",H4=""),"",IF(G4="",H4,IF(H4="",G4,H4+G4))) | M4: =IF(AND(K4="",L4=""),"",IF(L4="",K4,IF(K4="",L4,K4+L4)))
A5: GHQ 969 | B5: =IF(A5="","",IFERROR(VLOOKUP(A5,FLOTA!$A:$M,4,0)&" "&VLOOKUP(A5,FLOTA!$A:$M,3,0),"⚠ Patente no encontrada")) -> PRADO LAND CRUISER TOYOTA | C5: 46078 | D5: PENDIENTE | E5: AMORTIGUADORES TRASEROS | I5: =IF(AND(G5="",H5=""),"",IF(G5="",H5,IF(H5="",G5,H5+G5))) | M5: =IF(AND(K5="",L5=""),"",IF(L5="",K5,IF(K5="",L5,K5+L5)))
A6: GHQ 969 | B6: =IF(A6="","",IFERROR(VLOOKUP(A6,FLOTA!$A:$M,4,0)&" "&VLOOKUP(A6,FLOTA!$A:$M,3,0),"⚠ Patente no encontrada")) -> PRADO LAND CRUISER TOYOTA | C6: 46078 | D6: PENDIENTE | E6: AMORTIGUADORES DELANTEROS | I6: =IF(AND(G6="",H6=""),"",IF(G6="",H6,IF(H6="",G6,H6+G6))) | M6: =IF(AND(K6="",L6=""),"",IF(L6="",K6,IF(K6="",L6,K6+L6)))
A7: GHQ 969 | B7: =IF(A7="","",IFERROR(VLOOKUP(A7,FLOTA!$A:$M,4,0)&" "&VLOOKUP(A7,FLOTA!$A:$M,3,0),"⚠ Patente no encontrada")) -> PRADO LAND CRUISER TOYOTA | C7: 46078 | D7: PENDIENTE | E7: SERVICE DE FRENOS DELANTEROS | I7: =IF(AND(G7="",H7=""),"",IF(G7="",H7,IF(H7="",G7,H7+G7))) | M7: =IF(AND(K7="",L7=""),"",IF(L7="",K7,IF(K7="",L7,K7+L7)))
A8: GHQ 969 | B8: =IF(A8="","",IFERROR(VLOOKUP(A8,FLOTA!$A:$M,4,0)&" "&VLOOKUP(A8,FLOTA!$A:$M,3,0),"⚠ Patente no encontrada")) -> PRADO LAND CRUISER TOYOTA | C8: 46078 | D8: PENDIENTE | E8: SERVICE DE FRENOS TRASEROS | I8: =IF(AND(G8="",H8=""),"",IF(G8="",H8,IF(H8="",G8,H8+G8))) | M8: =IF(AND(K8="",L8=""),"",IF(L8="",K8,IF(K8="",L8,K8+L8)))
A9: GHQ 969 | B9: =IF(A9="","",IFERROR(VLOOKUP(A9,FLOTA!$A:$M,4,0)&" "&VLOOKUP(A9,FLOTA!$A:$M,3,0),"⚠ Patente no encontrada")) -> PRADO LAND CRUISER TOYOTA | C9: 46078 | D9: PENDIENTE | E9: SERVICE DE FRENO DE MANO | I9: =IF(AND(G9="",H9=""),"",IF(G9="",H9,IF(H9="",G9,H9+G9))) | M9: =IF(AND(K9="",L9=""),"",IF(L9="",K9,IF(K9="",L9,K9+L9)))
A10: GHQ 969 | B10: =IF(A10="","",IFERROR(VLOOKUP(A10,FLOTA!$A:$M,4,0)&" "&VLOOKUP(A10,FLOTA!$A:$M,3,0),"⚠ Patente no encontrada")) -> PRADO LAND CRUISER TOYOTA | C10: 46078 | D10: PENDIENTE | E10: REPARACION DE PARAGOLPE DELANTERO | I10: =IF(AND(G10="",H10=""),"",IF(G10="",H10,IF(H10="",G10,H10+G10))) | M10: =IF(AND(K10="",L10=""),"",IF(L10="",K10,IF(K10="",L10,K10+L10)))
A11: GHQ 969 | B11: =IF(A11="","",IFERROR(VLOOKUP(A11,FLOTA!$A:$M,4,0)&" "&VLOOKUP(A11,FLOTA!$A:$M,3,0),"⚠ Patente no encontrada")) -> PRADO LAND CRUISER TOYOTA | C11: 46078 | D11: PENDIENTE | E11: REPARACION DE OPTICAS DELANTERAS | I11: =IF(AND(G11="",H11=""),"",IF(G11="",H11,IF(H11="",G11,H11+G11))) | M11: =IF(AND(K11="",L11=""),"",IF(L11="",K11,IF(K11="",L11,K11+L11)))
A12: GHQ 969 | B12: =IF(A12="","",IFERROR(VLOOKUP(A12,FLOTA!$A:$M,4,0)&" "&VLOOKUP(A12,FLOTA!$A:$M,3,0),"⚠ Patente no encontrada")) -> PRADO LAND CRUISER TOYOTA | C12: 46078 | D12: PENDIENTE | E12: CAMBIO DE ESCOBILLAS | I12: =IF(AND(G12="",H12=""),"",IF(G12="",H12,IF(H12="",G12,H12+G12)))
A13: AA 757 MH | B13: =IF(A13="","",IFERROR(VLOOKUP(A13,FLOTA!$A:$M,4,0)&" "&VLOOKUP(A13,FLOTA!$A:$M,3,0),"⚠ Patente no encontrada")) -> TORO FIAT | C13: 46078 | D13: PENDIENTE | E13: SERVICE DE MOTOR | I13: =IF(AND(G13="",H13=""),"",IF(G13="",H13,IF(H13="",G13,H13+G13))) | M13: =IF(AND(K13="",L13=""),"",IF(L13="",K13,IF(K13="",L13,K13+L13)))
A14: AA 757 MH | B14: =IF(A14="","",IFERROR(VLOOKUP(A14,FLOTA!$A:$M,4,0)&" "&VLOOKUP(A14,FLOTA!$A:$M,3,0),"⚠ Patente no encontrada")) -> TORO FIAT | C14: 46078 | D14: PENDIENTE | E14: JUNTA DE HOMOCINETICA | I14: =IF(AND(G14="",H14=""),"",IF(G14="",H14,IF(H14="",G14,H14+G14))) | M14: =IF(AND(K14="",L14=""),"",IF(L14="",K14,IF(K14="",L14,K14+L14)))
A15: AA 757 MH | B15: =IF(A15="","",IFERROR(VLOOKUP(A15,FLOTA!$A:$M,4,0)&" "&VLOOKUP(A15,FLOTA!$A:$M,3,0),"⚠ Patente no encontrada")) -> TORO FIAT | C15: 46078 | D15: HECHO | E15: LAMPARAS PRINCIPALES QUEMADAS | I15: =IF(AND(G15="",H15=""),"",IF(G15="",H15,IF(H15="",G15,H15+G15))) | M15: =IF(AND(K15="",L15=""),"",IF(L15="",K15,IF(K15="",L15,K15+L15)))
A16: AA 757 MH | B16: =IF(A16="","",IFERROR(VLOOKUP(A16,FLOTA!$A:$M,4,0)&" "&VLOOKUP(A16,FLOTA!$A:$M,3,0),"⚠ Patente no encontrada")) -> TORO FIAT | C16: 46078 | D16: PENDIENTE | E16: CAMBIO DE PARABRISA DELANTERO | I16: =IF(AND(G16="",H16=""),"",IF(G16="",H16,IF(H16="",G16,H16+G16))) | M16: =IF(AND(K16="",L16=""),"",IF(L16="",K16,IF(K16="",L16,K16+L16)))
A17: AA 757 MH | B17: =IF(A17="","",IFERROR(VLOOKUP(A17,FLOTA!$A:$M,4,0)&" "&VLOOKUP(A17,FLOTA!$A:$M,3,0),"⚠ Patente no encontrada")) -> TORO FIAT | C17: 46078 | D17: PENDIENTE | E17: TREN DELANTERO COMPLETO | I17: =IF(AND(G17="",H17=""),"",IF(G17="",H17,IF(H17="",G17,H17+G17))) | M17: =IF(AND(K17="",L17=""),"",IF(L17="",K17,IF(K17="",L17,K17+L17)))
A18: AA 757 MH | B18: =IF(A18="","",IFERROR(VLOOKUP(A18,FLOTA!$A:$M,4,0)&" "&VLOOKUP(A18,FLOTA!$A:$M,3,0),"⚠ Patente no encontrada")) -> TORO FIAT | C18: 46078 | D18: PENDIENTE | E18: CAMBIO DE ESCOBILLAS | I18: =IF(AND(G18="",H18=""),"",IF(G18="",H18,IF(H18="",G18,H18+G18))) | M18: =IF(AND(K18="",L18=""),"",IF(L18="",K18,IF(K18="",L18,K18+L18)))
A19: AA 757 MH | B19: =IF(A19="","",IFERROR(VLOOKUP(A19,FLOTA!$A:$M,4,0)&" "&VLOOKUP(A19,FLOTA!$A:$M,3,0),"⚠ Patente no encontrada")) -> TORO FIAT | C19: 46078 | D19: PENDIENTE | E19: REPARACION COMPLETA DE SISTEMA A/C | I19: =IF(AND(G19="",H19=""),"",IF(G19="",H19,IF(H19="",G19,H19+G19)))
A20: PKF 116 | B20: =IF(A20="","",IFERROR(VLOOKUP(A20,FLOTA!$A:$M,4,0)&" "&VLOOKUP(A20,FLOTA!$A:$M,3,0),"⚠ Patente no encontrada")) -> SPRINTER 515 CDIC MERCEDES BENZ | C20: 46078 | D20: PENDIENTE | E20: SERVICE DE MOTOR | I20: =IF(AND(G20="",H20=""),"",IF(G20="",H20,IF(H20="",G20,H20+G20))) | M20: =IF(AND(K20="",L20=""),"",IF(L20="",K20,IF(K20="",L20,K20+L20)))
A21: PKF 116 | B21: =IF(A21="","",IFERROR(VLOOKUP(A21,FLOTA!$A:$M,4,0)&" "&VLOOKUP(A21,FLOTA!$A:$M,3,0),"⚠ Patente no encontrada")) -> SPRINTER 515 CDIC MERCEDES BENZ | C21: 46078 | D21: PENDIENTE | E21: FUGA POR CONEXIÓN | I21: =IF(AND(G21="",H21=""),"",IF(G21="",H21,IF(H21="",G21,H21+G21))) | M21: =IF(AND(K21="",L21=""),"",IF(L21="",K21,IF(K21="",L21,K21+L21)))
A22: PKF 116 | B22: =IF(A22="","",IFERROR(VLOOKUP(A22,FLOTA!$A:$M,4,0)&" "&VLOOKUP(A22,FLOTA!$A:$M,3,0),"⚠ Patente no encontrada")) -> SPRINTER 515 CDIC MERCEDES BENZ | C22: 46078 | D22: PENDIENTE | E22: GATO HIDRAULICO | I22: =IF(AND(G22="",H22=""),"",IF(G22="",H22,IF(H22="",G22,H22+G22))) | M22: =IF(AND(K22="",L22=""),"",IF(L22="",K22,IF(K22="",L22,K22+L22)))
A23: PKF 116 | B23: =IF(A23="","",IFERROR(VLOOKUP(A23,FLOTA!$A:$M,4,0)&" "&VLOOKUP(A23,FLOTA!$A:$M,3,0),"⚠ Patente no encontrada")) -> SPRINTER 515 CDIC MERCEDES BENZ | C23: 46078 | D23: PENDIENTE | E23: LAMPARAS PRINCIPALES QUEMADAS | I23: =IF(AND(G23="",H23=""),"",IF(G23="",H23,IF(H23="",G23,H23+G23))) | M23: =IF(AND(K23="",L23=""),"",IF(L23="",K23,IF(K23="",L23,K23+L23)))
A24: PKF 116 | B24: =IF(A24="","",IFERROR(VLOOKUP(A24,FLOTA!$A:$M,4,0)&" "&VLOOKUP(A24,FLOTA!$A:$M,3,0),"⚠ Patente no encontrada")) -> SPRINTER 515 CDIC MERCEDES BENZ | C24: 46078 | D24: PENDIENTE | E24: CAMBIO DE ESCOBILLAS | I24: =IF(AND(G24="",H24=""),"",IF(G24="",H24,IF(H24="",G24,H24+G24))) | M24: =IF(AND(K24="",L24=""),"",IF(L24="",K24,IF(K24="",L24,K24+L24)))
A25: AD 755 DX | B25: =IF(A25="","",IFERROR(VLOOKUP(A25,FLOTA!$A:$M,4,0)&" "&VLOOKUP(A25,FLOTA!$A:$M,3,0),"⚠ Patente no encontrada")) -> SPRINTER 515 CDIC MERCEDES BENZ | C25: 46078 | D25: PENDIENTE | E25: TREN DELANTERO COMPLETO | I25: =IF(AND(G25="",H25=""),"",IF(G25="",H25,IF(H25="",G25,H25+G25))) | M25: =IF(AND(K25="",L25=""),"",IF(L25="",K25,IF(K25="",L25,K25+L25)))
A26: AD 755 DX | B26: =IF(A26="","",IFERROR(VLOOKUP(A26,FLOTA!$A:$M,4,0)&" "&VLOOKUP(A26,FLOTA!$A:$M,3,0),"⚠ Patente no encontrada")) -> SPRINTER 515 CDIC MERCEDES BENZ | C26: 46078 | D26: PENDIENTE | E26: TREN TRASERO COMPLETO | I26: =IF(AND(G26="",H26=""),"",IF(G26="",H26,IF(H26="",G26,H26+G26))) | M26: =IF(AND(K26="",L26=""),"",IF(L26="",K26,IF(K26="",L26,K26+L26)))
A27: AD 755 DX | B27: =IF(A27="","",IFERROR(VLOOKUP(A27,FLOTA!$A:$M,4,0)&" "&VLOOKUP(A27,FLOTA!$A:$M,3,0),"⚠ Patente no encontrada")) -> SPRINTER 515 CDIC MERCEDES BENZ | C27: 46078 | D27: PENDIENTE | E27: LAMPARAS PRINCIPALES QUEMADAS | I27: =IF(AND(G27="",H27=""),"",IF(G27="",H27,IF(H27="",G27,H27+G27))) | M27: =IF(AND(K27="",L27=""),"",IF(L27="",K27,IF(K27="",L27,K27+L27)))
A28: AD 755 DX | B28: =IF(A28="","",IFERROR(VLOOKUP(A28,FLOTA!$A:$M,4,0)&" "&VLOOKUP(A28,FLOTA!$A:$M,3,0),"⚠ Patente no encontrada")) -> SPRINTER 515 CDIC MERCEDES BENZ | C28: 46078 | D28: PENDIENTE | E28: GATO HIDRAULICO | I28: =IF(AND(G28="",H28=""),"",IF(G28="",H28,IF(H28="",G28,H28+G28))) | M28: =IF(AND(K28="",L28=""),"",IF(L28="",K28,IF(K28="",L28,K28+L28)))
A29: AD 755 DX | B29: =IF(A29="","",IFERROR(VLOOKUP(A29,FLOTA!$A:$M,4,0)&" "&VLOOKUP(A29,FLOTA!$A:$M,3,0),"⚠ Patente no encontrada")) -> SPRINTER 515 CDIC MERCEDES BENZ | C29: 46078 | D29: PENDIENTE | E29: LLAVE DE AUXILIO | I29: =IF(AND(G29="",H29=""),"",IF(G29="",H29,IF(H29="",G29,H29+G29))) | M29: =IF(AND(K29="",L29=""),"",IF(L29="",K29,IF(K29="",L29,K29+L29)))
A30: AD 755 DX | B30: =IF(A30="","",IFERROR(VLOOKUP(A30,FLOTA!$A:$M,4,0)&" "&VLOOKUP(A30,FLOTA!$A:$M,3,0),"⚠ Patente no encontrada")) -> SPRINTER 515 CDIC MERCEDES BENZ | C30: 46078 | D30: PENDIENTE | E30: SENSOR DE RECIPIENTE DE LIQUIDO REFRIGERANTE | I30: =IF(AND(G30="",H30=""),"",IF(G30="",H30,IF(H30="",G30,H30+G30))) | M30: =IF(AND(K30="",L30=""),"",IF(L30="",K30,IF(K30="",L30,K30+L30)))
A31: AD 755 DX | B31: =IF(A31="","",IFERROR(VLOOKUP(A31,FLOTA!$A:$M,4,0)&" "&VLOOKUP(A31,FLOTA!$A:$M,3,0),"⚠ Patente no encontrada")) -> SPRINTER 515 CDIC MERCEDES BENZ | C31: 46078 | D31: PENDIENTE | E31: CAMBIO DE ESCOBILLAS | I31: =IF(AND(G31="",H31=""),"",IF(G31="",H31,IF(H31="",G31,H31+G31))) | M31: =IF(AND(K31="",L31=""),"",IF(L31="",K31,IF(K31="",L31,K31+L31)))
... A41: AA 757 OT | B41: =IF(A41="","",IFERROR(VLOOKUP(A41,FLOTA!$A:$M,4,0)&" "&VLOOKUP(A41,FLOTA!$A:$M,3,0),"⚠ Patente no encontrada")) -> HILUX 4X2 CD SRV 3.0 TOYOTA | C41: 46078 | D41: PENDIENTE | E41: CAMBIO DE OPTICAS DELANTERAS | I41: =IF(AND(G41="",H41=""),"",IF(G41="",H41,IF(H41="",G41,H41+G41))) | M41: =IF(AND(K41="",L41=""),"",IF(L41="",K41,IF(K41="",L41,K41+L41)))
A42: AA 757 OT | B42: =IF(A42="","",IFERROR(VLOOKUP(A42,FLOTA!$A:$M,4,0)&" "&VLOOKUP(A42,FLOTA!$A:$M,3,0),"⚠ Patente no encontrada")) -> HILUX 4X2 CD SRV 3.0 TOYOTA | C42: 46078 | D42: PENDIENTE | E42: CAMBIO DE ESCOBILLAS | I42: =IF(AND(G42="",H42=""),"",IF(G42="",H42,IF(H42="",G42,H42+G42)))
A43: MPR 852 | B43: =IF(A43="","",IFERROR(VLOOKUP(A43,FLOTA!$A:$M,4,0)&" "&VLOOKUP(A43,FLOTA!$A:$M,3,0),"⚠ Patente no encontrada")) -> AMAROK CD 2.0 4X4 180CV VOLKSWAGEN | C43: 46078 | D43: PENDIENTE | E43: CORREA POLI V KIT COMPLETO CON TENSOR | I43: =IF(AND(G43="",H43=""),"",IF(G43="",H43,IF(H43="",G43,H43+G43))) | M43: =IF(AND(K43="",L43=""),"",IF(L43="",K43,IF(K43="",L43,K43+L43)))
A44: MPR 852 | B44: =IF(A44="","",IFERROR(VLOOKUP(A44,FLOTA!$A:$M,4,0)&" "&VLOOKUP(A44,FLOTA!$A:$M,3,0),"⚠ Patente no encontrada")) -> AMAROK CD 2.0 4X4 180CV VOLKSWAGEN | C44: 46078 | D44: PENDIENTE | E44: REPARACION COMPLETA DE MOTOR | I44: =IF(AND(G44="",H44=""),"",IF(G44="",H44,IF(H44="",G44,H44+G44))) | M44: =IF(AND(K44="",L44=""),"",IF(L44="",K44,IF(K44="",L44,K44+L44)))
A45: MPR 852 | B45: =IF(A45="","",IFERROR(VLOOKUP(A45,FLOTA!$A:$M,4,0)&" "&VLOOKUP(A45,FLOTA!$A:$M,3,0),"⚠ Patente no encontrada")) -> AMAROK CD 2.0 4X4 180CV VOLKSWAGEN | C45: 46078 | D45: PENDIENTE | E45: PARABRISA DELANTERO | I45: =IF(AND(G45="",H45=""),"",IF(G45="",H45,IF(H45="",G45,H45+G45))) | M45: =IF(AND(K45="",L45=""),"",IF(L45="",K45,IF(K45="",L45,K45+L45)))
A46: MPR 852 | B46: =IF(A46="","",IFERROR(VLOOKUP(A46,FLOTA!$A:$M,4,0)&" "&VLOOKUP(A46,FLOTA!$A:$M,3,0),"⚠ Patente no encontrada")) -> AMAROK CD 2.0 4X4 180CV VOLKSWAGEN | C46: 46078 | D46: PENDIENTE | E46: SERVICE DE MOTOR | I46: =IF(AND(G46="",H46=""),"",IF(G46="",H46,IF(H46="",G46,H46+G46))) | M46: =IF(AND(K46="",L46=""),"",IF(L46="",K46,IF(K46="",L46,K46+L46)))
A47: MPR 852 | B47: =IF(A47="","",IFERROR(VLOOKUP(A47,FLOTA!$A:$M,4,0)&" "&VLOOKUP(A47,FLOTA!$A:$M,3,0),"⚠ Patente no encontrada")) -> AMAROK CD 2.0 4X4 180CV VOLKSWAGEN | C47: 46078 | D47: PENDIENTE | E47: REPARACION COMPLETA DE SISTEMA A/C | I47: =IF(AND(G47="",H47=""),"",IF(G47="",H47,IF(H47="",G47,H47+G47))) | M47: =IF(AND(K47="",L47=""),"",IF(L47="",K47,IF(K47="",L47,K47+L47)))
A48: MPR 852 | B48: =IF(A48="","",IFERROR(VLOOKUP(A48,FLOTA!$A:$M,4,0)&" "&VLOOKUP(A48,FLOTA!$A:$M,3,0),"⚠ Patente no encontrada")) -> AMAROK CD 2.0 4X4 180CV VOLKSWAGEN | C48: 46078 | D48: PENDIENTE | E48: RODAMIENTOS DE RUEDAS DELANTERAS | I48: =IF(AND(G48="",H48=""),"",IF(G48="",H48,IF(H48="",G48,H48+G48))) | M48: =IF(AND(K48="",L48=""),"",IF(L48="",K48,IF(K48="",L48,K48+L48)))
A49: MPR 852 | B49: =IF(A49="","",IFERROR(VLOOKUP(A49,FLOTA!$A:$M,4,0)&" "&VLOOKUP(A49,FLOTA!$A:$M,3,0),"⚠ Patente no encontrada")) -> AMAROK CD 2.0 4X4 180CV VOLKSWAGEN | C49: 46078 | D49: PENDIENTE | E49: CAMBIO DE ESCOBILLAS | I49: =IF(AND(G49="",H49=""),"",IF(G49="",H49,IF(H49="",G49,H49+G49))) | M49: =IF(AND(K49="",L49=""),"",IF(L49="",K49,IF(K49="",L49,K49+L49)))
...
